{
 "cells": [
  {
   "cell_type": "code",
   "execution_count": 1,
   "metadata": {},
   "outputs": [],
   "source": [
    "%matplotlib inline\n",
    "import h5py\n",
    "import os\n",
    "import matplotlib.pyplot as plt\n",
    "import numpy as np\n",
    "import pandas as pd\n",
    "import cv2\n",
    "import tensorflow as tf\n",
    "from tensorflow.keras.models import Sequential, Model\n",
    "from tensorflow.keras.layers import Conv2D, MaxPooling2D, Flatten, Dense, Dropout, Activation, Input\n",
    "from tensorflow.keras.optimizers import SGD\n",
    "from sklearn.preprocessing import LabelEncoder, OneHotEncoder, LabelBinarizer\n",
    "\n",
    "from tensorflow.keras.applications import ResNet50\n",
    "from tensorflow.keras.applications import InceptionV3\n",
    "from tensorflow.keras.applications import Xception  # TensorFlow ONLY\n",
    "from tensorflow.keras.applications import VGG16, VGG19, InceptionV3\n",
    "from tensorflow.keras.applications import imagenet_utils\n",
    "from tensorflow.keras.applications.inception_v3 import preprocess_input\n",
    "from tensorflow.keras.preprocessing.image import img_to_array, load_img\n",
    "from tensorflow.keras.preprocessing.image import ImageDataGenerator\n",
    "from tensorflow.keras.callbacks import ModelCheckpoint, LearningRateScheduler, TensorBoard, EarlyStopping\n",
    "\n",
    "import warnings\n",
    "warnings.filterwarnings('ignore')"
   ]
  },
  {
   "cell_type": "code",
   "execution_count": 2,
   "metadata": {},
   "outputs": [],
   "source": [
    "models_filename = '/Users/Barbara/Desktop/Ironhack/Final_Project/food-101/v8-vgg16-model-1/v8_vgg16_model_1.h5'\n",
    "image_dir = '/Users/Barbara/Desktop/Ironhack/Final_Project/food-101/food-101/images'\n",
    "image_size = (224, 224)\n",
    "batch_size = 16\n",
    "epochs = 80"
   ]
  },
  {
   "cell_type": "code",
   "execution_count": 3,
   "metadata": {},
   "outputs": [
    {
     "name": "stdout",
     "output_type": "stream",
     "text": [
      "Found 101000 images belonging to 101 classes.\n"
     ]
    }
   ],
   "source": [
    "# 5gb of images won't fit in my memory. use datagenerator to go across all images.\n",
    "train_datagen = ImageDataGenerator(\n",
    "rescale = 1./255,\n",
    "horizontal_flip = False,\n",
    "fill_mode = \"nearest\",\n",
    "zoom_range = 0,\n",
    "width_shift_range = 0,\n",
    "height_shift_range=0,\n",
    "rotation_range=0)\n",
    "\n",
    "train_generator = train_datagen.flow_from_directory(\n",
    "image_dir,\n",
    "target_size = (image_size[0], image_size[1]),\n",
    "batch_size = batch_size, \n",
    "class_mode = \"categorical\")\n",
    "\n",
    "num_of_classes = len(train_generator.class_indices)"
   ]
  },
  {
   "cell_type": "code",
   "execution_count": 4,
   "metadata": {},
   "outputs": [
    {
     "name": "stderr",
     "output_type": "stream",
     "text": [
      "2024-07-08 19:03:03.954266: I metal_plugin/src/device/metal_device.cc:1154] Metal device set to: Apple M3 Pro\n",
      "2024-07-08 19:03:03.954313: I metal_plugin/src/device/metal_device.cc:296] systemMemory: 18.00 GB\n",
      "2024-07-08 19:03:03.954325: I metal_plugin/src/device/metal_device.cc:313] maxCacheSize: 6.00 GB\n",
      "2024-07-08 19:03:03.954599: I tensorflow/core/common_runtime/pluggable_device/pluggable_device_factory.cc:305] Could not identify NUMA node of platform GPU ID 0, defaulting to 0. Your kernel may not have been built with NUMA support.\n",
      "2024-07-08 19:03:03.954641: I tensorflow/core/common_runtime/pluggable_device/pluggable_device_factory.cc:271] Created TensorFlow device (/job:localhost/replica:0/task:0/device:GPU:0 with 0 MB memory) -> physical PluggableDevice (device: 0, name: METAL, pci bus id: <undefined>)\n"
     ]
    }
   ],
   "source": [
    "model = VGG16(weights=None, include_top=False, input_shape=(image_size[0], image_size[1], 3))\n",
    "\n",
    "#Adding custom Layers \n",
    "x = model.output\n",
    "x = Flatten()(x)\n",
    "x = Dense(101*2, activation=\"relu\")(x)\n",
    "x = Dense(101*2, activation=\"relu\")(x)\n",
    "predictions = Dense(101, activation=\"softmax\")(x)\n",
    "model_final = Model(input=model.input, output=predictions)\n",
    "model_final.compile(loss=\"categorical_crossentropy\", optimizer='adam', metrics=[\"accuracy\"])\n",
    "model_final.load_weights(models_filename)"
   ]
  },
  {
   "cell_type": "code",
   "execution_count": 6,
   "metadata": {},
   "outputs": [
    {
     "name": "stdout",
     "output_type": "stream",
     "text": [
      "Num GPUs Available:  1\n",
      "Found 101000 images belonging to 101 classes.\n",
      "Epoch 1/80\n"
     ]
    },
    {
     "name": "stderr",
     "output_type": "stream",
     "text": [
      "2024-07-09 09:13:38.534312: I tensorflow/core/grappler/optimizers/custom_graph_optimizer_registry.cc:117] Plugin optimizer for device_type GPU is enabled.\n",
      "2024-07-09 09:13:52.755348: I tensorflow/core/kernels/data/shuffle_dataset_op.cc:450] ShuffleDatasetV3:2: Filling up shuffle buffer (this may take a while): 3 of 8\n",
      "2024-07-09 09:14:10.056315: I tensorflow/core/kernels/data/shuffle_dataset_op.cc:450] ShuffleDatasetV3:2: Filling up shuffle buffer (this may take a while): 7 of 8\n",
      "2024-07-09 09:14:13.611211: I tensorflow/core/kernels/data/shuffle_dataset_op.cc:480] Shuffle buffer filled.\n"
     ]
    },
    {
     "name": "stdout",
     "output_type": "stream",
     "text": [
      "\u001b[1m2433/6312\u001b[0m \u001b[32m━━━━━━━\u001b[0m\u001b[37m━━━━━━━━━━━━━\u001b[0m \u001b[1m4:51:07\u001b[0m 5s/step - accuracy: 0.0096 - loss: 4.6928"
     ]
    },
    {
     "name": "stderr",
     "output_type": "stream",
     "text": [
      "2024-07-09 12:16:48.399239: W tensorflow/core/framework/op_kernel.cc:1827] UNKNOWN: TimeoutError: [Errno 60] Operation timed out\n",
      "Traceback (most recent call last):\n",
      "\n",
      "  File \"/Applications/Utilities/anaconda3/envs/tensorflow_macos/lib/python3.9/site-packages/tensorflow/python/ops/script_ops.py\", line 270, in __call__\n",
      "    ret = func(*args)\n",
      "\n",
      "  File \"/Applications/Utilities/anaconda3/envs/tensorflow_macos/lib/python3.9/site-packages/tensorflow/python/autograph/impl/api.py\", line 643, in wrapper\n",
      "    return func(*args, **kwargs)\n",
      "\n",
      "  File \"/Applications/Utilities/anaconda3/envs/tensorflow_macos/lib/python3.9/site-packages/tensorflow/python/data/ops/from_generator_op.py\", line 198, in generator_py_func\n",
      "    values = next(generator_state.get_iterator(iterator_id))\n",
      "\n",
      "  File \"/Applications/Utilities/anaconda3/envs/tensorflow_macos/lib/python3.9/site-packages/keras/src/trainers/data_adapters/py_dataset_adapter.py\", line 260, in _get_iterator\n",
      "    for i, batch in enumerate(gen_fn()):\n",
      "\n",
      "  File \"/Applications/Utilities/anaconda3/envs/tensorflow_macos/lib/python3.9/site-packages/keras/src/trainers/data_adapters/py_dataset_adapter.py\", line 253, in generator_fn\n",
      "    yield self.py_dataset[i]\n",
      "\n",
      "  File \"/Applications/Utilities/anaconda3/envs/tensorflow_macos/lib/python3.9/site-packages/keras/src/legacy/preprocessing/image.py\", line 68, in __getitem__\n",
      "    return self._get_batches_of_transformed_samples(index_array)\n",
      "\n",
      "  File \"/Applications/Utilities/anaconda3/envs/tensorflow_macos/lib/python3.9/site-packages/keras/src/legacy/preprocessing/image.py\", line 313, in _get_batches_of_transformed_samples\n",
      "    img = image_utils.load_img(\n",
      "\n",
      "  File \"/Applications/Utilities/anaconda3/envs/tensorflow_macos/lib/python3.9/site-packages/keras/src/utils/image_utils.py\", line 236, in load_img\n",
      "    img = pil_image.open(io.BytesIO(f.read()))\n",
      "\n",
      "TimeoutError: [Errno 60] Operation timed out\n",
      "\n",
      "\n",
      "2024-07-09 12:16:48.399552: W tensorflow/core/framework/local_rendezvous.cc:404] Local rendezvous is aborting with status: UNKNOWN: TimeoutError: [Errno 60] Operation timed out\n",
      "Traceback (most recent call last):\n",
      "\n",
      "  File \"/Applications/Utilities/anaconda3/envs/tensorflow_macos/lib/python3.9/site-packages/tensorflow/python/ops/script_ops.py\", line 270, in __call__\n",
      "    ret = func(*args)\n",
      "\n",
      "  File \"/Applications/Utilities/anaconda3/envs/tensorflow_macos/lib/python3.9/site-packages/tensorflow/python/autograph/impl/api.py\", line 643, in wrapper\n",
      "    return func(*args, **kwargs)\n",
      "\n",
      "  File \"/Applications/Utilities/anaconda3/envs/tensorflow_macos/lib/python3.9/site-packages/tensorflow/python/data/ops/from_generator_op.py\", line 198, in generator_py_func\n",
      "    values = next(generator_state.get_iterator(iterator_id))\n",
      "\n",
      "  File \"/Applications/Utilities/anaconda3/envs/tensorflow_macos/lib/python3.9/site-packages/keras/src/trainers/data_adapters/py_dataset_adapter.py\", line 260, in _get_iterator\n",
      "    for i, batch in enumerate(gen_fn()):\n",
      "\n",
      "  File \"/Applications/Utilities/anaconda3/envs/tensorflow_macos/lib/python3.9/site-packages/keras/src/trainers/data_adapters/py_dataset_adapter.py\", line 253, in generator_fn\n",
      "    yield self.py_dataset[i]\n",
      "\n",
      "  File \"/Applications/Utilities/anaconda3/envs/tensorflow_macos/lib/python3.9/site-packages/keras/src/legacy/preprocessing/image.py\", line 68, in __getitem__\n",
      "    return self._get_batches_of_transformed_samples(index_array)\n",
      "\n",
      "  File \"/Applications/Utilities/anaconda3/envs/tensorflow_macos/lib/python3.9/site-packages/keras/src/legacy/preprocessing/image.py\", line 313, in _get_batches_of_transformed_samples\n",
      "    img = image_utils.load_img(\n",
      "\n",
      "  File \"/Applications/Utilities/anaconda3/envs/tensorflow_macos/lib/python3.9/site-packages/keras/src/utils/image_utils.py\", line 236, in load_img\n",
      "    img = pil_image.open(io.BytesIO(f.read()))\n",
      "\n",
      "TimeoutError: [Errno 60] Operation timed out\n",
      "\n",
      "\n",
      "\t [[{{node PyFunc}}]]\n",
      "\t [[IteratorGetNext]]\n",
      "2024-07-09 12:16:48.399565: W tensorflow/core/framework/local_rendezvous.cc:404] Local rendezvous is aborting with status: UNKNOWN: TimeoutError: [Errno 60] Operation timed out\n",
      "Traceback (most recent call last):\n",
      "\n",
      "  File \"/Applications/Utilities/anaconda3/envs/tensorflow_macos/lib/python3.9/site-packages/tensorflow/python/ops/script_ops.py\", line 270, in __call__\n",
      "    ret = func(*args)\n",
      "\n",
      "  File \"/Applications/Utilities/anaconda3/envs/tensorflow_macos/lib/python3.9/site-packages/tensorflow/python/autograph/impl/api.py\", line 643, in wrapper\n",
      "    return func(*args, **kwargs)\n",
      "\n",
      "  File \"/Applications/Utilities/anaconda3/envs/tensorflow_macos/lib/python3.9/site-packages/tensorflow/python/data/ops/from_generator_op.py\", line 198, in generator_py_func\n",
      "    values = next(generator_state.get_iterator(iterator_id))\n",
      "\n",
      "  File \"/Applications/Utilities/anaconda3/envs/tensorflow_macos/lib/python3.9/site-packages/keras/src/trainers/data_adapters/py_dataset_adapter.py\", line 260, in _get_iterator\n",
      "    for i, batch in enumerate(gen_fn()):\n",
      "\n",
      "  File \"/Applications/Utilities/anaconda3/envs/tensorflow_macos/lib/python3.9/site-packages/keras/src/trainers/data_adapters/py_dataset_adapter.py\", line 253, in generator_fn\n",
      "    yield self.py_dataset[i]\n",
      "\n",
      "  File \"/Applications/Utilities/anaconda3/envs/tensorflow_macos/lib/python3.9/site-packages/keras/src/legacy/preprocessing/image.py\", line 68, in __getitem__\n",
      "    return self._get_batches_of_transformed_samples(index_array)\n",
      "\n",
      "  File \"/Applications/Utilities/anaconda3/envs/tensorflow_macos/lib/python3.9/site-packages/keras/src/legacy/preprocessing/image.py\", line 313, in _get_batches_of_transformed_samples\n",
      "    img = image_utils.load_img(\n",
      "\n",
      "  File \"/Applications/Utilities/anaconda3/envs/tensorflow_macos/lib/python3.9/site-packages/keras/src/utils/image_utils.py\", line 236, in load_img\n",
      "    img = pil_image.open(io.BytesIO(f.read()))\n",
      "\n",
      "TimeoutError: [Errno 60] Operation timed out\n",
      "\n",
      "\n",
      "\t [[{{node PyFunc}}]]\n",
      "\t [[IteratorGetNext]]\n",
      "\t [[IteratorGetNext/_5]]\n",
      "2024-07-09 12:16:48.399574: I tensorflow/core/framework/local_rendezvous.cc:422] Local rendezvous recv item cancelled. Key hash: 4965105943420077669\n",
      "2024-07-09 12:16:48.399579: I tensorflow/core/framework/local_rendezvous.cc:422] Local rendezvous recv item cancelled. Key hash: 11433077755212859593\n",
      "2024-07-09 12:16:48.399584: I tensorflow/core/framework/local_rendezvous.cc:422] Local rendezvous recv item cancelled. Key hash: 7865194918585354557\n",
      "2024-07-09 12:16:48.399588: I tensorflow/core/framework/local_rendezvous.cc:422] Local rendezvous recv item cancelled. Key hash: 10675329843694599039\n",
      "2024-07-09 12:16:48.399601: I tensorflow/core/framework/local_rendezvous.cc:422] Local rendezvous recv item cancelled. Key hash: 6418287940357362128\n",
      "2024-07-09 12:16:48.399645: I tensorflow/core/framework/local_rendezvous.cc:422] Local rendezvous recv item cancelled. Key hash: 11258932515911725442\n",
      "2024-07-09 12:16:48.399654: I tensorflow/core/framework/local_rendezvous.cc:422] Local rendezvous recv item cancelled. Key hash: 17963841948216747920\n"
     ]
    },
    {
     "ename": "UnknownError",
     "evalue": "Graph execution error:\n\nDetected at node PyFunc defined at (most recent call last):\n<stack traces unavailable>\nDetected at node PyFunc defined at (most recent call last):\n<stack traces unavailable>\n2 root error(s) found.\n  (0) UNKNOWN:  TimeoutError: [Errno 60] Operation timed out\nTraceback (most recent call last):\n\n  File \"/Applications/Utilities/anaconda3/envs/tensorflow_macos/lib/python3.9/site-packages/tensorflow/python/ops/script_ops.py\", line 270, in __call__\n    ret = func(*args)\n\n  File \"/Applications/Utilities/anaconda3/envs/tensorflow_macos/lib/python3.9/site-packages/tensorflow/python/autograph/impl/api.py\", line 643, in wrapper\n    return func(*args, **kwargs)\n\n  File \"/Applications/Utilities/anaconda3/envs/tensorflow_macos/lib/python3.9/site-packages/tensorflow/python/data/ops/from_generator_op.py\", line 198, in generator_py_func\n    values = next(generator_state.get_iterator(iterator_id))\n\n  File \"/Applications/Utilities/anaconda3/envs/tensorflow_macos/lib/python3.9/site-packages/keras/src/trainers/data_adapters/py_dataset_adapter.py\", line 260, in _get_iterator\n    for i, batch in enumerate(gen_fn()):\n\n  File \"/Applications/Utilities/anaconda3/envs/tensorflow_macos/lib/python3.9/site-packages/keras/src/trainers/data_adapters/py_dataset_adapter.py\", line 253, in generator_fn\n    yield self.py_dataset[i]\n\n  File \"/Applications/Utilities/anaconda3/envs/tensorflow_macos/lib/python3.9/site-packages/keras/src/legacy/preprocessing/image.py\", line 68, in __getitem__\n    return self._get_batches_of_transformed_samples(index_array)\n\n  File \"/Applications/Utilities/anaconda3/envs/tensorflow_macos/lib/python3.9/site-packages/keras/src/legacy/preprocessing/image.py\", line 313, in _get_batches_of_transformed_samples\n    img = image_utils.load_img(\n\n  File \"/Applications/Utilities/anaconda3/envs/tensorflow_macos/lib/python3.9/site-packages/keras/src/utils/image_utils.py\", line 236, in load_img\n    img = pil_image.open(io.BytesIO(f.read()))\n\nTimeoutError: [Errno 60] Operation timed out\n\n\n\t [[{{node PyFunc}}]]\n\t [[IteratorGetNext]]\n\t [[IteratorGetNext/_5]]\n  (1) UNKNOWN:  TimeoutError: [Errno 60] Operation timed out\nTraceback (most recent call last):\n\n  File \"/Applications/Utilities/anaconda3/envs/tensorflow_macos/lib/python3.9/site-packages/tensorflow/python/ops/script_ops.py\", line 270, in __call__\n    ret = func(*args)\n\n  File \"/Applications/Utilities/anaconda3/envs/tensorflow_macos/lib/python3.9/site-packages/tensorflow/python/autograph/impl/api.py\", line 643, in wrapper\n    return func(*args, **kwargs)\n\n  File \"/Applications/Utilities/anaconda3/envs/tensorflow_macos/lib/python3.9/site-packages/tensorflow/python/data/ops/from_generator_op.py\", line 198, in generator_py_func\n    values = next(generator_state.get_iterator(iterator_id))\n\n  File \"/Applications/Utilities/anaconda3/envs/tensorflow_macos/lib/python3.9/site-packages/keras/src/trainers/data_adapters/py_dataset_adapter.py\", line 260, in _get_iterator\n    for i, batch in enumerate(gen_fn()):\n\n  File \"/Applications/Utilities/anaconda3/envs/tensorflow_macos/lib/python3.9/site-packages/keras/src/trainers/data_adapters/py_dataset_adapter.py\", line 253, in generator_fn\n    yield self.py_dataset[i]\n\n  File \"/Applications/Utilities/anaconda3/envs/tensorflow_macos/lib/python3.9/site-packages/keras/src/legacy/preprocessing/image.py\", line 68, in __getitem__\n    return self._get_batches_of_transformed_samples(index_array)\n\n  File \"/Applications/Utilities/anaconda3/envs/tensorflow_macos/lib/python3.9/site-packages/keras/src/legacy/preprocessing/image.py\", line 313, in _get_batches_of_transformed_samples\n    img = image_utils.load_img(\n\n  File \"/Applications/Utilities/anaconda3/envs/tensorflow_macos/lib/python3.9/site-packages/keras/src/utils/image_utils.py\", line 236, in load_img\n    img = pil_image.open(io.BytesIO(f.read()))\n\nTimeoutError: [Errno 60] Operation timed out\n\n\n\t [[{{node PyFunc}}]]\n\t [[IteratorGetNext]]\n0 successful operations.\n0 derived errors ignored. [Op:__inference_one_step_on_iterator_5946]",
     "output_type": "error",
     "traceback": [
      "\u001b[0;31m---------------------------------------------------------------------------\u001b[0m",
      "\u001b[0;31mUnknownError\u001b[0m                              Traceback (most recent call last)",
      "Cell \u001b[0;32mIn[6], line 85\u001b[0m\n\u001b[1;32m     82\u001b[0m callbacks \u001b[38;5;241m=\u001b[39m [checkpoint, early_stopping, tensorboard]\n\u001b[1;32m     84\u001b[0m \u001b[38;5;66;03m# Train the model\u001b[39;00m\n\u001b[0;32m---> 85\u001b[0m \u001b[43mmodel_final\u001b[49m\u001b[38;5;241;43m.\u001b[39;49m\u001b[43mfit\u001b[49m\u001b[43m(\u001b[49m\n\u001b[1;32m     86\u001b[0m \u001b[43m    \u001b[49m\u001b[43mtrain_generator\u001b[49m\u001b[43m,\u001b[49m\n\u001b[1;32m     87\u001b[0m \u001b[43m    \u001b[49m\u001b[43msteps_per_epoch\u001b[49m\u001b[38;5;241;43m=\u001b[39;49m\u001b[43mtrain_generator\u001b[49m\u001b[38;5;241;43m.\u001b[39;49m\u001b[43msamples\u001b[49m\u001b[43m \u001b[49m\u001b[38;5;241;43m/\u001b[39;49m\u001b[38;5;241;43m/\u001b[39;49m\u001b[43m \u001b[49m\u001b[43mbatch_size\u001b[49m\u001b[43m,\u001b[49m\n\u001b[1;32m     88\u001b[0m \u001b[43m    \u001b[49m\u001b[43mepochs\u001b[49m\u001b[38;5;241;43m=\u001b[39;49m\u001b[43mepochs\u001b[49m\u001b[43m,\u001b[49m\n\u001b[1;32m     89\u001b[0m \u001b[43m    \u001b[49m\u001b[43mcallbacks\u001b[49m\u001b[38;5;241;43m=\u001b[39;49m\u001b[43mcallbacks\u001b[49m\n\u001b[1;32m     90\u001b[0m \u001b[43m)\u001b[49m\n",
      "File \u001b[0;32m/Applications/Utilities/anaconda3/envs/tensorflow_macos/lib/python3.9/site-packages/keras/src/utils/traceback_utils.py:122\u001b[0m, in \u001b[0;36mfilter_traceback.<locals>.error_handler\u001b[0;34m(*args, **kwargs)\u001b[0m\n\u001b[1;32m    119\u001b[0m     filtered_tb \u001b[38;5;241m=\u001b[39m _process_traceback_frames(e\u001b[38;5;241m.\u001b[39m__traceback__)\n\u001b[1;32m    120\u001b[0m     \u001b[38;5;66;03m# To get the full stack trace, call:\u001b[39;00m\n\u001b[1;32m    121\u001b[0m     \u001b[38;5;66;03m# `keras.config.disable_traceback_filtering()`\u001b[39;00m\n\u001b[0;32m--> 122\u001b[0m     \u001b[38;5;28;01mraise\u001b[39;00m e\u001b[38;5;241m.\u001b[39mwith_traceback(filtered_tb) \u001b[38;5;28;01mfrom\u001b[39;00m \u001b[38;5;28;01mNone\u001b[39;00m\n\u001b[1;32m    123\u001b[0m \u001b[38;5;28;01mfinally\u001b[39;00m:\n\u001b[1;32m    124\u001b[0m     \u001b[38;5;28;01mdel\u001b[39;00m filtered_tb\n",
      "File \u001b[0;32m/Applications/Utilities/anaconda3/envs/tensorflow_macos/lib/python3.9/site-packages/tensorflow/python/eager/execute.py:53\u001b[0m, in \u001b[0;36mquick_execute\u001b[0;34m(op_name, num_outputs, inputs, attrs, ctx, name)\u001b[0m\n\u001b[1;32m     51\u001b[0m \u001b[38;5;28;01mtry\u001b[39;00m:\n\u001b[1;32m     52\u001b[0m   ctx\u001b[38;5;241m.\u001b[39mensure_initialized()\n\u001b[0;32m---> 53\u001b[0m   tensors \u001b[38;5;241m=\u001b[39m pywrap_tfe\u001b[38;5;241m.\u001b[39mTFE_Py_Execute(ctx\u001b[38;5;241m.\u001b[39m_handle, device_name, op_name,\n\u001b[1;32m     54\u001b[0m                                       inputs, attrs, num_outputs)\n\u001b[1;32m     55\u001b[0m \u001b[38;5;28;01mexcept\u001b[39;00m core\u001b[38;5;241m.\u001b[39m_NotOkStatusException \u001b[38;5;28;01mas\u001b[39;00m e:\n\u001b[1;32m     56\u001b[0m   \u001b[38;5;28;01mif\u001b[39;00m name \u001b[38;5;129;01mis\u001b[39;00m \u001b[38;5;129;01mnot\u001b[39;00m \u001b[38;5;28;01mNone\u001b[39;00m:\n",
      "\u001b[0;31mUnknownError\u001b[0m: Graph execution error:\n\nDetected at node PyFunc defined at (most recent call last):\n<stack traces unavailable>\nDetected at node PyFunc defined at (most recent call last):\n<stack traces unavailable>\n2 root error(s) found.\n  (0) UNKNOWN:  TimeoutError: [Errno 60] Operation timed out\nTraceback (most recent call last):\n\n  File \"/Applications/Utilities/anaconda3/envs/tensorflow_macos/lib/python3.9/site-packages/tensorflow/python/ops/script_ops.py\", line 270, in __call__\n    ret = func(*args)\n\n  File \"/Applications/Utilities/anaconda3/envs/tensorflow_macos/lib/python3.9/site-packages/tensorflow/python/autograph/impl/api.py\", line 643, in wrapper\n    return func(*args, **kwargs)\n\n  File \"/Applications/Utilities/anaconda3/envs/tensorflow_macos/lib/python3.9/site-packages/tensorflow/python/data/ops/from_generator_op.py\", line 198, in generator_py_func\n    values = next(generator_state.get_iterator(iterator_id))\n\n  File \"/Applications/Utilities/anaconda3/envs/tensorflow_macos/lib/python3.9/site-packages/keras/src/trainers/data_adapters/py_dataset_adapter.py\", line 260, in _get_iterator\n    for i, batch in enumerate(gen_fn()):\n\n  File \"/Applications/Utilities/anaconda3/envs/tensorflow_macos/lib/python3.9/site-packages/keras/src/trainers/data_adapters/py_dataset_adapter.py\", line 253, in generator_fn\n    yield self.py_dataset[i]\n\n  File \"/Applications/Utilities/anaconda3/envs/tensorflow_macos/lib/python3.9/site-packages/keras/src/legacy/preprocessing/image.py\", line 68, in __getitem__\n    return self._get_batches_of_transformed_samples(index_array)\n\n  File \"/Applications/Utilities/anaconda3/envs/tensorflow_macos/lib/python3.9/site-packages/keras/src/legacy/preprocessing/image.py\", line 313, in _get_batches_of_transformed_samples\n    img = image_utils.load_img(\n\n  File \"/Applications/Utilities/anaconda3/envs/tensorflow_macos/lib/python3.9/site-packages/keras/src/utils/image_utils.py\", line 236, in load_img\n    img = pil_image.open(io.BytesIO(f.read()))\n\nTimeoutError: [Errno 60] Operation timed out\n\n\n\t [[{{node PyFunc}}]]\n\t [[IteratorGetNext]]\n\t [[IteratorGetNext/_5]]\n  (1) UNKNOWN:  TimeoutError: [Errno 60] Operation timed out\nTraceback (most recent call last):\n\n  File \"/Applications/Utilities/anaconda3/envs/tensorflow_macos/lib/python3.9/site-packages/tensorflow/python/ops/script_ops.py\", line 270, in __call__\n    ret = func(*args)\n\n  File \"/Applications/Utilities/anaconda3/envs/tensorflow_macos/lib/python3.9/site-packages/tensorflow/python/autograph/impl/api.py\", line 643, in wrapper\n    return func(*args, **kwargs)\n\n  File \"/Applications/Utilities/anaconda3/envs/tensorflow_macos/lib/python3.9/site-packages/tensorflow/python/data/ops/from_generator_op.py\", line 198, in generator_py_func\n    values = next(generator_state.get_iterator(iterator_id))\n\n  File \"/Applications/Utilities/anaconda3/envs/tensorflow_macos/lib/python3.9/site-packages/keras/src/trainers/data_adapters/py_dataset_adapter.py\", line 260, in _get_iterator\n    for i, batch in enumerate(gen_fn()):\n\n  File \"/Applications/Utilities/anaconda3/envs/tensorflow_macos/lib/python3.9/site-packages/keras/src/trainers/data_adapters/py_dataset_adapter.py\", line 253, in generator_fn\n    yield self.py_dataset[i]\n\n  File \"/Applications/Utilities/anaconda3/envs/tensorflow_macos/lib/python3.9/site-packages/keras/src/legacy/preprocessing/image.py\", line 68, in __getitem__\n    return self._get_batches_of_transformed_samples(index_array)\n\n  File \"/Applications/Utilities/anaconda3/envs/tensorflow_macos/lib/python3.9/site-packages/keras/src/legacy/preprocessing/image.py\", line 313, in _get_batches_of_transformed_samples\n    img = image_utils.load_img(\n\n  File \"/Applications/Utilities/anaconda3/envs/tensorflow_macos/lib/python3.9/site-packages/keras/src/utils/image_utils.py\", line 236, in load_img\n    img = pil_image.open(io.BytesIO(f.read()))\n\nTimeoutError: [Errno 60] Operation timed out\n\n\n\t [[{{node PyFunc}}]]\n\t [[IteratorGetNext]]\n0 successful operations.\n0 derived errors ignored. [Op:__inference_one_step_on_iterator_5946]"
     ]
    }
   ],
   "source": [
    "%matplotlib inline\n",
    "import os\n",
    "import matplotlib.pyplot as plt\n",
    "import numpy as np\n",
    "import pandas as pd\n",
    "import cv2\n",
    "import tensorflow as tf\n",
    "from tensorflow.keras.models import Sequential, Model\n",
    "from tensorflow.keras.layers import Conv2D, MaxPooling2D, Flatten, Dense, Dropout, Activation, Input\n",
    "from tensorflow.keras.optimizers import SGD\n",
    "from sklearn.preprocessing import LabelEncoder, OneHotEncoder, LabelBinarizer\n",
    "from tensorflow.keras.applications import VGG16\n",
    "from tensorflow.keras.preprocessing.image import img_to_array, load_img, ImageDataGenerator\n",
    "from tensorflow.keras.callbacks import ModelCheckpoint, LearningRateScheduler, TensorBoard, EarlyStopping\n",
    "import warnings\n",
    "\n",
    "warnings.filterwarnings('ignore')\n",
    "\n",
    "# Ensure TensorFlow uses the GPU\n",
    "gpus = tf.config.list_physical_devices('GPU')\n",
    "if gpus:\n",
    "    try:\n",
    "        for gpu in gpus:\n",
    "            tf.config.experimental.set_memory_growth(gpu, True)\n",
    "    except RuntimeError as e:\n",
    "        print(e)\n",
    "\n",
    "print(\"Num GPUs Available: \", len(tf.config.list_physical_devices('GPU')))\n",
    "\n",
    "# File paths and parameters\n",
    "models_filename = '/Users/Barbara/Desktop/Ironhack/Final_Project/food-101/v8-vgg16-model-1/v8_vgg16_model_1.keras'\n",
    "image_dir = '/Users/Barbara/Desktop/Ironhack/Final_Project/food-101/food-101/images'\n",
    "image_size = (224, 224)\n",
    "batch_size = 16\n",
    "epochs = 80\n",
    "\n",
    "# Data augmentation and data generator\n",
    "train_datagen = ImageDataGenerator(\n",
    "    rescale=1./255,\n",
    "    horizontal_flip=True,\n",
    "    fill_mode=\"nearest\",\n",
    "    zoom_range=0.2,\n",
    "    width_shift_range=0.2,\n",
    "    height_shift_range=0.2,\n",
    "    rotation_range=30\n",
    ")\n",
    "\n",
    "train_generator = train_datagen.flow_from_directory(\n",
    "    image_dir,\n",
    "    target_size=image_size,\n",
    "    batch_size=batch_size,\n",
    "    class_mode=\"categorical\"\n",
    ")\n",
    "\n",
    "num_of_classes = len(train_generator.class_indices)\n",
    "\n",
    "# Load the base model\n",
    "base_model = VGG16(weights='imagenet', include_top=False, input_shape=(image_size[0], image_size[1], 3))\n",
    "\n",
    "# Add custom layers\n",
    "x = base_model.output\n",
    "x = Flatten()(x)\n",
    "x = Dense(512, activation=\"relu\")(x)\n",
    "x = Dense(512, activation=\"relu\")(x)\n",
    "predictions = Dense(num_of_classes, activation=\"softmax\")(x)\n",
    "\n",
    "# Create the final model\n",
    "model_final = Model(inputs=base_model.input, outputs=predictions)\n",
    "\n",
    "# Compile the model\n",
    "model_final.compile(loss=\"categorical_crossentropy\", optimizer='adam', metrics=[\"accuracy\"])\n",
    "\n",
    "# Load weights if available\n",
    "if os.path.exists(models_filename):\n",
    "    model_final.load_weights(models_filename)\n",
    "\n",
    "# Callbacks\n",
    "checkpoint = ModelCheckpoint(\"best_model.keras\", monitor='loss', verbose=1, save_best_only=True, mode='min')\n",
    "early_stopping = EarlyStopping(monitor='loss', patience=10, verbose=1, mode='min')\n",
    "tensorboard = TensorBoard(log_dir='./logs', histogram_freq=0, write_graph=True, write_images=False)\n",
    "\n",
    "callbacks = [checkpoint, early_stopping, tensorboard]\n",
    "\n",
    "# Train the model\n",
    "model_final.fit(\n",
    "    train_generator,\n",
    "    steps_per_epoch=train_generator.samples // batch_size,\n",
    "    epochs=epochs,\n",
    "    callbacks=callbacks\n",
    ")"
   ]
  },
  {
   "cell_type": "code",
   "execution_count": null,
   "metadata": {},
   "outputs": [],
   "source": [
    "preds = model_final.evaluate_generator(train_generator, steps=800, workers=8, use_multiprocessing=True)\n",
    "preds"
   ]
  },
  {
   "cell_type": "code",
   "execution_count": null,
   "metadata": {},
   "outputs": [],
   "source": [
    "# routine for human evaluation - use the generator so we can see how well it can predict\n",
    "for n in range(100):\n",
    "    _ = train_generator.next()\n",
    "    image, classifier = (_[0][0],_[1][0]) # take the first image from the batch\n",
    "    index = np.argmax(classifier)\n",
    "    answer = list(train_generator.class_indices.keys())[index]\n",
    "    predicted = model_final.predict(np.asarray([image]))\n",
    "    predicted_answer_index = np.argmax(predicted[0])\n",
    "    predicted_answer = list(train_generator.class_indices.keys())[predicted_answer_index]\n",
    "\n",
    "    plt.imshow(image)\n",
    "    plt.show()\n",
    "\n",
    "    print('correct answer is: ', answer)\n",
    "    print()\n",
    "    print('CNN thinks it''s:', predicted_answer)"
   ]
  }
 ],
 "metadata": {
  "kernelspec": {
   "display_name": "tensorflow_macos",
   "language": "python",
   "name": "python3"
  },
  "language_info": {
   "codemirror_mode": {
    "name": "ipython",
    "version": 3
   },
   "file_extension": ".py",
   "mimetype": "text/x-python",
   "name": "python",
   "nbconvert_exporter": "python",
   "pygments_lexer": "ipython3",
   "version": "3.9.19"
  }
 },
 "nbformat": 4,
 "nbformat_minor": 2
}
